Workbook
Name YearList: OFFSET('BN DASH DATA'!$X$4,0,0,SUMPRODUCT(--('BN DASH DATA'!$X$4:$X$12<>"")),1)

Sheet BN DASHBOARD
B2: BN LOGISTICS — SALES & FLEET DASHBOARD
B3: =IF($K$3="All years","Auburn brokerage + market loads + fleet utilisation · all history","Auburn brokerage + market loads + fleet utilisation · calendar year "&$K$3) -> Auburn brokerage + market loads + fleet utilisation · calendar year 2026 | J3: VIEW YEAR | K3: 2026
B5: TOTAL SALE | D5: AUBURN BILLED | F5: LORRY COST | H5: AUBURN MARGIN % | J5: LOADS | L5: FLEET USE
B6: =SUMIFS(AUBURN[BILLING RATE (₹)],AUBURN[LOADING DATE],">="&$C$61,AUBURN[LOADING DATE],"<="&$C$62)+SUMIFS(MARKET[RATE (₹)],MARKET[LOAD DATE],">="&$C$61,MARKET[LOAD DATE],"<="&$C$62) -> 30912850 | D6: =SUMIFS(AUBURN[BILLING RATE (₹)],AUBURN[LOADING DATE],">="&$C$61,AUBURN[LOADING DATE],"<="&$C$62) -> 26390330 | F6: =SUMIFS(AUBURN[LORRY RATE (₹)],AUBURN[LOADING DATE],">="&$C$61,AUBURN[LOADING DATE],"<="&$C$62) -> 13666890 | H6: =IFERROR(($D$6-$F$6)/$D$6,"") -> 0.48212508 | J6: =COUNTIFS(AUBURN[LOADING DATE],">="&$C$61,AUBURN[LOADING DATE],"<="&$C$62)+COUNTIFS(MARKET[LOAD DATE],">="&$C$61,MARKET[LOAD DATE],"<="&$C$62) -> 419 | L6: =IF($G$21=0,"n/a",$F$21/$G$21) -> 0.70046667
B7: =TEXT($D$6,"₹#,##0")&" from Auburn" -> ₹26,390,330 from Auburn | D7: =TEXT($F$6,"₹#,##0")&" paid to lorries" -> ₹13,666,890 paid to lorries | F7: =TEXT($D$6-$F$6,"₹#,##0")&" gross margin" -> ₹12,723,440 gross margin | H7: ="on "&TEXT(COUNTIFS(AUBURN[LOADING DATE],">="&$C$61,AUBURN[LOADING DATE],"<="&$C$62),"#,##0")&" Auburn loads" -> on 295 Auburn loads | J7: =TEXT(COUNTIFS(MARKET[LOAD DATE],">="&$C$61,MARKET[LOAD DATE],"<="&$C$62),"#,##0")&" market loads" -> 124 market loads | L7: =IF($G$21=0,"km log starts Mar-2026",TEXT($F$21,"#,##0")&" km run") -> 630,420 km run
B9: =IF($G$21=0,"PER-TRUCK UTILISATION — no KM log for "&$K$3&" (log starts Mar-2026)","PER-TRUCK UTILISATION") -> PER-TRUCK UTILISATION
B10: TRUCK | C10: MAKE | D10: CAPACITY | E10: DRIVER | F10: ACTUAL KM | G10: TARGET KM | H10: UTILISATION %
B11: 2417 | C11: =IFERROR(INDEX(KMRUN[MAKE],MATCH($B11,KMRUN[TRUCK NO.],0)),"") -> Tata | D11: =IFERROR(INDEX(KMRUN[CAPACITY],MATCH($B11,KMRUN[TRUCK NO.],0)),"") -> 32 Feet | E11: =IFERROR(INDEX(KMRUN[DRIVER],MATCH($B11,KMRUN[TRUCK NO.],0)),"") -> Driver A | F11: =SUMIFS(KMRUN[ACTUAL KM],KMRUN[TRUCK NO.],$B11,KMRUN[MONTH],">="&$C$61,KMRUN[MONTH],"<="&$C$62) -> 70130 | G11: =SUMIFS(KMRUN[TARGET KM],KMRUN[TRUCK NO.],$B11,KMRUN[MONTH],">="&$C$61,KMRUN[MONTH],"<="&$C$62) -> 90000 | H11: =IFERROR($F11/$G11,"") -> 0.77922222
B12: 0526 | C12: =IFERROR(INDEX(KMRUN[MAKE],MATCH($B12,KMRUN[TRUCK NO.],0)),"") -> Tata | D12: =IFERROR(INDEX(KMRUN[CAPACITY],MATCH($B12,KMRUN[TRUCK NO.],0)),"") -> 32 Feet | E12: =IFERROR(INDEX(KMRUN[DRIVER],MATCH($B12,KMRUN[TRUCK NO.],0)),"") -> Driver B | F12: =SUMIFS(KMRUN[ACTUAL KM],KMRUN[TRUCK NO.],$B12,KMRUN[MONTH],">="&$C$61,KMRUN[MONTH],"<="&$C$62) -> 73250 | G12: =SUMIFS(KMRUN[TARGET KM],KMRUN[TRUCK NO.],$B12,KMRUN[MONTH],">="&$C$61,KMRUN[MONTH],"<="&$C$62) -> 90000 | H12: =IFERROR($F12/$G12,"") -> 0.81388889
B13: 3958 | C13: =IFERROR(INDEX(KMRUN[MAKE],MATCH($B13,KMRUN[TRUCK NO.],0)),"") -> Tata | D13: =IFERROR(INDEX(KMRUN[CAPACITY],MATCH($B13,KMRUN[TRUCK NO.],0)),"") -> 32 Feet | E13: =IFERROR(INDEX(KMRUN[DRIVER],MATCH($B13,KMRUN[TRUCK NO.],0)),"") -> Driver C | F13: =SUMIFS(KMRUN[ACTUAL KM],KMRUN[TRUCK NO.],$B13,KMRUN[MONTH],">="&$C$61,KMRUN[MONTH],"<="&$C$62) -> 73250 | G13: =SUMIFS(KMRUN[TARGET KM],KMRUN[TRUCK NO.],$B13,KMRUN[MONTH],">="&$C$61,KMRUN[MONTH],"<="&$C$62) -> 90000 | H13: =IFERROR($F13/$G13,"") -> 0.81388889
B14: 6142 | C14: =IFERROR(INDEX(KMRUN[MAKE],MATCH($B14,KMRUN[TRUCK NO.],0)),"") -> Tata | D14: =IFERROR(INDEX(KMRUN[CAPACITY],MATCH($B14,KMRUN[TRUCK NO.],0)),"") -> 32 Feet | E14: =IFERROR(INDEX(KMRUN[DRIVER],MATCH($B14,KMRUN[TRUCK NO.],0)),"") -> Driver D | F14: =SUMIFS(KMRUN[ACTUAL KM],KMRUN[TRUCK NO.],$B14,KMRUN[MONTH],">="&$C$61,KMRUN[MONTH],"<="&$C$62) -> 78320 | G14: =SUMIFS(KMRUN[TARGET KM],KMRUN[TRUCK NO.],$B14,KMRUN[MONTH],">="&$C$61,KMRUN[MONTH],"<="&$C$62) -> 90000 | H14: =IFERROR($F14/$G14,"") -> 0.87022222
B15: 8803 | C15: =IFERROR(INDEX(KMRUN[MAKE],MATCH($B15,KMRUN[TRUCK NO.],0)),"") -> Ashok | D15: =IFERROR(INDEX(KMRUN[CAPACITY],MATCH($B15,KMRUN[TRUCK NO.],0)),"") -> 32 Feet | E15: =IFERROR(INDEX(KMRUN[DRIVER],MATCH($B15,KMRUN[TRUCK NO.],0)),"") -> Driver E | F15: =SUMIFS(KMRUN[ACTUAL KM],KMRUN[TRUCK NO.],$B15,KMRUN[MONTH],">="&$C$61,KMRUN[MONTH],"<="&$C$62) -> 68000 | G15: =SUMIFS(KMRUN[TARGET KM],KMRUN[TRUCK NO.],$B15,KMRUN[MONTH],">="&$C$61,KMRUN[MONTH],"<="&$C$62) -> 90000 | H15: =IFERROR($F15/$G15,"") -> 0.75555556
B16: 4371 | C16: =IFERROR(INDEX(KMRUN[MAKE],MATCH($B16,KMRUN[TRUCK NO.],0)),"") -> Ashok | D16: =IFERROR(INDEX(KMRUN[CAPACITY],MATCH($B16,KMRUN[TRUCK NO.],0)),"") -> 24 Feet | E16: =IFERROR(INDEX(KMRUN[DRIVER],MATCH($B16,KMRUN[TRUCK NO.],0)),"") -> Driver F | F16: =SUMIFS(KMRUN[ACTUAL KM],KMRUN[TRUCK NO.],$B16,KMRUN[MONTH],">="&$C$61,KMRUN[MONTH],"<="&$C$62) -> 57150 | G16: =SUMIFS(KMRUN[TARGET KM],KMRUN[TRUCK NO.],$B16,KMRUN[MONTH],">="&$C$61,KMRUN[MONTH],"<="&$C$62) -> 90000 | H16: =IFERROR($F16/$G16,"") -> 0.635
B17: 1695 | C17: =IFERROR(INDEX(KMRUN[MAKE],MATCH($B17,KMRUN[TRUCK NO.],0)),"") -> Tata | D17: =IFERROR(INDEX(KMRUN[CAPACITY],MATCH($B17,KMRUN[TRUCK NO.],0)),"") -> 32 Feet | E17: =IFERROR(INDEX(KMRUN[DRIVER],MATCH($B17,KMRUN[TRUCK NO.],0)),"") -> Driver G | F17: =SUMIFS(KMRUN[ACTUAL KM],KMRUN[TRUCK NO.],$B17,KMRUN[MONTH],">="&$C$61,KMRUN[MONTH],"<="&$C$62) -> 61100 | G17: =SUMIFS(KMRUN[TARGET KM],KMRUN[TRUCK NO.],$B17,KMRUN[MONTH],">="&$C$61,KMRUN[MONTH],"<="&$C$62) -> 90000 | H17: =IFERROR($F17/$G17,"") -> 0.67888889
B18: 7230 | C18: =IFERROR(INDEX(KMRUN[MAKE],MATCH($B18,KMRUN[TRUCK NO.],0)),"") -> Tata | D18: =IFERROR(INDEX(KMRUN[CAPACITY],MATCH($B18,KMRUN[TRUCK NO.],0)),"") -> 32 Feet | E18: =IFERROR(INDEX(KMRUN[DRIVER],MATCH($B18,KMRUN[TRUCK NO.],0)),"") -> Driver H | F18: =SUMIFS(KMRUN[ACTUAL KM],KMRUN[TRUCK NO.],$B18,KMRUN[MONTH],">="&$C$61,KMRUN[MONTH],"<="&$C$62) -> 58420 | G18: =SUMIFS(KMRUN[TARGET KM],KMRUN[TRUCK NO.],$B18,KMRUN[MONTH],">="&$C$61,KMRUN[MONTH],"<="&$C$62) -> 90000 | H18: =IFERROR($F18/$G18,"") -> 0.64911111
B19: 9064 | C19: =IFERROR(INDEX(KMRUN[MAKE],MATCH($B19,KMRUN[TRUCK NO.],0)),"") -> Tata | D19: =IFERROR(INDEX(KMRUN[CAPACITY],MATCH($B19,KMRUN[TRUCK NO.],0)),"") -> 32 Feet | E19: =IFERROR(INDEX(KMRUN[DRIVER],MATCH($B19,KMRUN[TRUCK NO.],0)),"") -> Driver I | F19: =SUMIFS(KMRUN[ACTUAL KM],KMRUN[TRUCK NO.],$B19,KMRUN[MONTH],">="&$C$61,KMRUN[MONTH],"<="&$C$62) -> 47300 | G19: =SUMIFS(KMRUN[TARGET KM],KMRUN[TRUCK NO.],$B19,KMRUN[MONTH],">="&$C$61,KMRUN[MONTH],"<="&$C$62) -> 90000 | H19: =IFERROR($F19/$G19,"") -> 0.52555556
B20: 5582 | C20: =IFERROR(INDEX(KMRUN[MAKE],MATCH($B20,KMRUN[TRUCK NO.],0)),"") -> Tata | D20: =IFERROR(INDEX(KMRUN[CAPACITY],MATCH($B20,KMRUN[TRUCK NO.],0)),"") -> 32 Feet | E20: =IFERROR(INDEX(KMRUN[DRIVER],MATCH($B20,KMRUN[TRUCK NO.],0)),"") -> Driver J | F20: =SUMIFS(KMRUN[ACTUAL KM],KMRUN[TRUCK NO.],$B20,KMRUN[MONTH],">="&$C$61,KMRUN[MONTH],"<="&$C$62) -> 43500 | G20: =SUMIFS(KMRUN[TARGET KM],KMRUN[TRUCK NO.],$B20,KMRUN[MONTH],">="&$C$61,KMRUN[MONTH],"<="&$C$62) -> 90000 | H20: =IFERROR($F20/$G20,"") -> 0.48333333
B21: FLEET | F21: =SUM(F11:F20) -> 630420 | G21: =SUM(G11:G20) -> 900000 | H21: =IFERROR($F$21/$G$21,"") -> 0.70046667
B23: MONTHLY REVENUE — AUBURN vs MARKET
B40: AUBURN MARGIN % TREND | H40: UTILISATION BY TRUCK
B57: =IF($K$3="All years","Charts show each calendar month totalled across 2024–2026. Auburn margin = billing rate less lorry rate. Market loads are own trucks, so no lorry cost applies. Fleet km log starts Mar-2026.","Charts show Jan–Dec of the selected year and respond to VIEW YEAR. Auburn margin = billing rate less lorry rate. Market loads are own trucks, so no lorry cost applies. Fleet km log starts Mar-2026.") -> Charts show Jan–Dec of the selected year and respond to VIEW YEAR. Auburn margin = billing rate less lorry rate. Market loads are own trucks, so no lorry cost applies. Fleet km log starts Mar-2026.
B60: Filter bounds (helper — driven by VIEW YEAR)
B61: FROM | C61: =IF($K$3="All years",DATE(1990,1,1),DATE($K$3,1,1)) -> 46023
B62: TO | C62: =IF($K$3="All years",DATE(2100,12,31),DATE($K$3,12,31)) -> 46387

Sheet Auburn Load 
A1: S.NO. | B1: Month | C1: LOADING DATE | D1: Provider | E1: LORRY NO. | F1: MOBILE NO. | G1: FROM | H1: POINT GR NO. | I1: TO GR NO. | J1: LORRY MAKE | K1: LORRY RATE | L1: Billing Rate Charges | M1: Net Saving | N1: Adance Paid (INR) | O1: Balance To pay | P1: BILL STATUS | Q1: Invoice No. | R1: Payment Status | S1: REACH UNLOADING POINT | T1: UNLOADING DATE | U1: Current Status | V1: BROAKER ADRESS | W1: REMARKS
A2: 1 | B2: May | C2: 10.05.2024 | D2: 3rd Party | E2: TN52TM-7760 | F2: 9686844715 | G2: RANCHI | H2: HASSAN.176610,BOX 04 | I2: BOMMANSA.562608,BOX 578 | J2: 32FEET SXL | K2: 38590 | L2: 46620 | M2: =Table1[[#This Row],[Billing Rate Charges]]-Table1[[#This Row],[ LORRY RATE ]] -> 8030 | N2: 38590 | O2: =Table1[[#This Row],[ LORRY RATE ]]-Table1[[#This Row],[Adance Paid (INR)]] -> 0 | P2: DONE | Q2: 01 | R2: RECEIPT | S2: SAME DAY | T2: 15/05/2024./18/05/2024 | U2: Closed | V2: Transporter 01
A3: 2 | B3: May | C3: 15.05.2024 | D3: 3rd Party | E3: TN52TM-1398 | F3: 9941053951 | G3: RANCHI | H3: HOSKOTE.749378,BOX 983 | I3: HASSAN,772300,BOX 004 | J3: 32FEET SXL | K3: 36450 | L3: 46620 | M3: =Table1[[#This Row],[Billing Rate Charges]]-Table1[[#This Row],[ LORRY RATE ]] -> 10170 | N3: 36450 | O3: =Table1[[#This Row],[ LORRY RATE ]]-Table1[[#This Row],[Adance Paid (INR)]] -> 0 | P3: DONE | Q3: 02 | R3: RECEIPT | S3: 45431 | T3: 20/05/2024./22/05/2024 | U3: Closed | V3: Transporter 02
A4: 3 | B4: May | C4: 45431 | D4: 3rd Party | E4: KA05TT-6944 | F4: 9295512602 | G4: RANCHI | H4: NARSAPUR.043922.BOX | I4: HASSAN,978172.BOX | J4: 24FEET | K4: 31930 | L4: 45040 | M4: =Table1[[#This Row],[Billing Rate Charges]]-Table1[[#This Row],[ LORRY RATE ]] -> 13110 | N4: 31930 | O4: =Table1[[#This Row],[ LORRY RATE ]]-Table1[[#This Row],[Adance Paid (INR)]] -> 0 | P4: DONE | Q4: 03 | R4: RECEIPT | S4: 45433 | T4: 21/05/2024./22/05/2024 | U4: Closed | V4: Transporter 02
A5: 4 | B5: May | C5: 45430 | D5: 3rd Party | E5: KA02GM-9724 | F5: 9149905009 | G5: RANCHI | H5: N/A | I5: HASSAN.909686.BOX 312 | J5: 22FEET | K5: 28300 | L5: 38740 | M5: =Table1[[#This Row],[Billing Rate Charges]]-Table1[[#This Row],[ LORRY RATE ]] -> 10440 | N5: 28300 | O5: =Table1[[#This Row],[ LORRY RATE ]]-Table1[[#This Row],[Adance Paid (INR)]] -> 0 | P5: DONE | Q5: 04 | R5: RECEIPT | S5: 45433 | T5: 45433 | U5: Closed | V5: Transporter 02
A6: 5 | B6: May | C6: 45431 | D6: 3rd Party | E6: TN12RW-1972 | F6: 9678275995 | G6: RANCHI | H6: N/A | I6: HOSKOTE.125550.BOX 729 | J6: 20FEET | K6: 27830 | L6: 35600 | M6: =Table1[[#This Row],[Billing Rate Charges]]-Table1[[#This Row],[ LORRY RATE ]] -> 7770 | N6: 27830 | O6: =Table1[[#This Row],[ LORRY RATE ]]-Table1[[#This Row],[Adance Paid (INR)]] -> 0 | P6: DONE | Q6: 05 | R6: RECEIPT | S6: 45433 | T6: 45433 | U6: Closed | V6: Transporter 02
A7: 6 | B7: May | C7: 45436 | D7: 3rd Party | E7: KA51DJ-2589 | F7: 9087547668 | G7: RANCHI | H7: NARSAPUR,803363 | I7: HOSKOTE,467212 | J7: 20FEET | K7: 29850 | L7: 41900 | M7: =Table1[[#This Row],[Billing Rate Charges]]-Table1[[#This Row],[ LORRY RATE ]] -> 12050 | N7: 29850 | O7: =Table1[[#This Row],[ LORRY RATE ]]-Table1[[#This Row],[Adance Paid (INR)]] -> 0 | P7: DONE | Q7: 06 | R7: RECEIPT | S7: 45440 | T7: 45440 | U7: Closed | V7: Transporter 02
A8: 7 | B8: May | C8: 45442 | D8: 3rd Party | E8: PB13MM-3286 | F8: 9757815238 | G8: RANCHI | H8: N/A | I8: HOKOTE,579908 | J8: 32FEET SXL | K8: 32290 | L8: 40320 | M8: =Table1[[#This Row],[Billing Rate Charges]]-Table1[[#This Row],[ LORRY RATE ]] -> 8030 | N8: 32290 | O8: =Table1[[#This Row],[ LORRY RATE ]]-Table1[[#This Row],[Adance Paid (INR)]] -> 0 | P8: DONE | Q8: 07 | R8: RECEIPT | S8: 45417 | T8: 45417 | U8: Closed | V8: Transporter 01
A9: 9 | B9: May | C9: 45436 | D9: BN | E9: JH01KM-4371 | F9: 9025368773 | G9: RANCHI | H9: N/A | I9: HOSKOTE,749252 | J9: 24FEET SXL | K9: 43990 | L9: 38740 | M9: =Table1[[#This Row],[Billing Rate Charges]]-Table1[[#This Row],[ LORRY RATE ]] -> -5250 | P9: DONE | Q9: 08 | R9: RECEIPT | S9: 45439 | T9: 45440 | U9: Closed | V9: BN
A10: 10 | B10: May | C10: 45440 | D10: BN | E10: JH01KM-4371 | F10: 9025368773 | G10: HOSKOTE | H10: BOMMANHALLI | I10: DODABALLAPUR | J10: 24FEET SXL | L10: 6300 | M10: =Table1[[#This Row],[Billing Rate Charges]]-Table1[[#This Row],[ LORRY RATE ]] -> 6300 | P10: DONE | Q10: 09 | R10: RECEIPT | S10: LOADING | U10: Closed | V10: BN
A11: 11 | B11: May | C11: 45442 | D11: BN | E11: JH01KM-4371 | F11: 9025368773 | G11: DODABALLAPUR | H11: N/A | I11: RANCHI ,872415/27 | J11: 24FEET SXL | K11: 48290 | L11: 67410 | M11: =Table1[[#This Row],[Billing Rate Charges]]-Table1[[#This Row],[ LORRY RATE ]] -> 19120 | P11: DONE | Q11: 09 | R11: RECEIPT | S11: 45445 | T11: 45446 | U11: Closed | V11: BN
A12: 12 | B12: May | C12: 45436 | D12: BN | E12: JH01KM-8803 | F12: 9589264337 | G12: RANCHI | H12: N/A | I12: HOSKOTE ,140915 | J12: 32FEET SXL | K12: 44220 | L12: 40320 | M12: =L12-K12 -> -3900 | P12: DONE | Q12: 10 | R12: RECEIPT | S12: 45439 | T12: 45439 | U12: Closed | V12: BN
A13: 13 | B13: May | C13: 45439 | D13: BN | E13: JH01KM-8803 | F13: 9589264337 | G13: TIRUPUR | H13: N/A | I13: RANCHI,407449 | J13: 32FEET SXL | K13: 51030 | L13: 85680 | M13: =L13-K13 -> 34650 | P13: DONE | Q13: 011 | R13: RECEIPT | S13: 45443 | T13: 45443 | U13: Closed | V13: BN
A14: 14 | B14: JUNE | C14: 45444 | D14: 3rd Party | E14: KA02YH-5646 | F14: 9198923795 | G14: RANCHI | H14: N/A | I14: HOSKOTE,264810 | J14: 20FEET | K14: 27290 | L14: 35600 | M14: 8310 | N14: 27290 | O14: =Table1[[#This Row],[ LORRY RATE ]]-Table1[[#This Row],[Adance Paid (INR)]] -> 0 | P14: DONE | Q14: 012 | R14: RECEIPT | S14: 45447 | T14: 45447 | U14: closed | V14: Transporter 02
A15: 15 | B15: JUNE | C15: 45444 | D15: 3rd Party | E15: KA05RX-6944 | F15: 9295512602 | G15: RANCHI | H15: N/A | I15: HASSAN,872860 | J15: 24FEET | K15: 29110 | L15: 38740 | M15: =Table1[[#This Row],[Billing Rate Charges]]-Table1[[#This Row],[ LORRY RATE ]] -> 9630 | N15: 29110 | O15: =Table1[[#This Row],[ LORRY RATE ]]-Table1[[#This Row],[Adance Paid (INR)]] -> 0 | P15: DONE | Q15: 013 | R15: RECEIPT | S15: 45447 | T15: 45447 | U15: closed | V15: Transporter 02
A16: 16 | B16: JUNE | C16: 45444 | D16: BN | E16: JH01KM-8803 | F16: 9589264337 | G16: RANCHI | H16: N/A | I16: HASSAN,913653 | J16: 32FEET SXL | K16: 44220 | L16: 40320 | M16: =Table1[[#This Row],[Billing Rate Charges]]-Table1[[#This Row],[ LORRY RATE ]] -> -3900 | P16: DONE | Q16: 014 | R16: RECEIPT | S16: 45448 | T16: 45448 | U16: closed | V16: BN
A17: 17 | B17: JUNE | C17: 45446 | D17: BN | E17: JH01KM-4371 | F17: 9025368773 | G17: RANCHI | H17: NARSAPUR,970325+HOSKOTE,425534 | I17: BOMMANSANDRA ,890248 | J17: 24 FEET SXL | K17: 45880 | L17: 51340 | M17: =Table1[[#This Row],[Billing Rate Charges]]-Table1[[#This Row],[ LORRY RATE ]] -> 5460 | P17: DONE | Q17: 015 | R17: RECEIPT | S17: 45449 | T17: 45450 | U17: closed | V17: BN
A18: 18 | B18: JUNE | C18: 45449 | D18: BN | E18: JH01KM8803 | F18: 9589264337 | G18: TIRUPUR | H18: N/A | I18: RANCHI,476477 | J18: 32 FEET SXL | K18: 51690 | L18: 90090 | M18: =Table1[[#This Row],[Billing Rate Charges]]-Table1[[#This Row],[ LORRY RATE ]] -> 38400 | P18: DONE | Q18: 016 | R18: RECEIPT | S18: 45452 | T18: 45453 | U18: closed | V18: BN
A19: 19 | B19: JUNE | C19: 45450 | D19: 3rd Party | E19: KA02GM-9724 | F19: 9149905009 | G19: RANCHI | H19: BOMMANSANDRA,933942 | I19: HOSKOTE,387835 | J19: 22FEET | K19: 27640 | L19: 45040 | M19: =Table1[[#This Row],[Billing Rate Charges]]-Table1[[#This Row],[ LORRY RATE ]] -> 17400 | N19: 27640 | O19: =Table1[[#This Row],[ LORRY RATE ]]-Table1[[#This Row],[Adance Paid (INR)]] -> 0 | P19: DONE | Q19: 017 | R19: RECEIPT | S19: 45454 | T19: 45454 | U19: closed | V19: Transporter 02
A20: 20 | B20: JUNE | C20: 45450 | D20: BN | E20: JH01KM-4371 | F20: 9025368773 | G20: ERODE | H20: N/A | I20: RANCHI,187030 | J20: 24FEET | K20: 48290 | L20: 67410 | M20: =Table1[[#This Row],[Billing Rate Charges]]-Table1[[#This Row],[ LORRY RATE ]] -> 19120 | P20: DONE | Q20: 018 | R20: RECEIPT | S20: 45452 | T20: 45453 | U20: closed | V20: BN
A21: 21 | B21: JUNE | C21: 45455 | D21: BN | E21: JH01KM-4371 | F21: 9025368773 | G21: RANCHI | H21: HOSKOTE,900316 | I21: BOMMANSA,863494 | J21: 24FEET | K21: 44930 | L21: 45040 | M21: =Table1[[#This Row],[Billing Rate Charges]]-Table1[[#This Row],[ LORRY RATE ]] -> 110 | P21: DONE | Q21: 019 | R21: RECEIPT | S21: 45458 | T21: 45458 | U21: closed | V21: BN
A22: 22 | B22: JUNE | C22: 45456 | D22: BN | E22: JH01KM-8803 | F22: 9589264337 | G22: RANCHI | H22: NARSAPUR,763576 | I22: BOMMANSANDRA,516517 | J22: 32FEET SXL | K22: 45170 | L22: 46620 | M22: =Table1[[#This Row],[Billing Rate Charges]]-Table1[[#This Row],[ LORRY RATE ]] -> 1450 | P22: DONE | Q22: 020 | R22: RECEIPT | S22: 45459 | T22: 45462 | U22: closed | V22: BN | W22: LORRY HALTING - EXTRA CHARGE
A23: 23 | B23: JUNE | C23: 45457 | D23: 3rd Party | E23: WB23J-3143 | F23: 9372267009 | G23: ERODE | H23: N/A | I23: RANCHI,241257 | J23: 32FEET MXL | K23: 75570 | L23: 93240 | M23: =Table1[[#This Row],[Billing Rate Charges]]-Table1[[#This Row],[ LORRY RATE ]] -> 17670 | N23: 75570 | O23: =Table1[[#This Row],[ LORRY RATE ]]-Table1[[#This Row],[Adance Paid (INR)]] -> 0 | P23: DONE | Q23: 021 | R23: RECEIPT | S23: 19-06-2024 | T23: 19-06-2024 | U23: closed | V23: Transporter 03
A24: 24 | B24: JUNE | C24: 45458 | D24: 3rd Party | E24: KA05TT-6944 | F24: 9295512602 | G24: RANCHI | H24: N/A | I24: HASSAN,857821 | J24: 24FEET | K24: 27770 | L24: 38740 | M24: =Table1[[#This Row],[Billing Rate Charges]]-Table1[[#This Row],[ LORRY RATE ]] -> 10970 | N24: 27770 | O24: =Table1[[#This Row],[ LORRY RATE ]]-Table1[[#This Row],[Adance Paid (INR)]] -> 0 | P24: DONE | Q24: 022 | R24: RECEIPT | S24: 19-06-2024 | T24: 19-06-2024 | U24: closed | V24: Transporter 02
A25: 25 | B25: JUNE | C25: 45459 | D25: BN | E25: JH01KM-4371 | F25: 9025368773 | G25: ERODE | H25: N/A | I25: RANCHI,454688 | J25: 24FEET | K25: 48290 | L25: 67410 | M25: =Table1[[#This Row],[Billing Rate Charges]]-Table1[[#This Row],[ LORRY RATE ]] -> 19120 | P25: DONE | Q25: 023 | R25: RECEIPT | S25: 18-06-2024 | T25: 18-06-2024 | U25: closed | V25: BN | W25: OVERLOAD - EXTRA CHARGE
A26: 26 | B26: JUNE | C26: 45460 | D26: 3rd Party | E26: KA53T-7407 | F26: 9684865656 | G26: RANCHI | H26: NARSAPUR,795057 | I26: HASSAN,857821 | J26: 20FEET | K26: 26100 | L26: 41900 | M26: =Table1[[#This Row],[Billing Rate Charges]]-Table1[[#This Row],[ LORRY RATE ]] -> 15800 | N26: 26100 | O26: =Table1[[#This Row],[ LORRY RATE ]]-Table1[[#This Row],[Adance Paid (INR)]] -> 0 | P26: DONE | Q26: 025 | R26: RECEIPT | S26: 21-06-2024 | T26: 22-06-2024 | U26: closed | V26: Transporter 02
A27: 27 | B27: JUNE | C27: 45462 | D27: BN | E27: JH01KM-4371 | F27: 9025368773 | G27: RANCHI | H27: N/A | I27: HASSAN,493930 | J27: 24FEET | K27: 46520 | L27: 55600 | M27: =Table1[[#This Row],[Billing Rate Charges]]-Table1[[#This Row],[ LORRY RATE ]] -> 9080 | P27: DONE | Q27: 024 | R27: RECEIPT | S27: 22-06-2024 | T27: 22-06-2024 | U27: closed | V27: BN
A28: 28 | B28: JUNE | C28: 45463 | D28: BN | E28: JH01KM-8803 | F28: 9589264337 | G28: TIRUPUR,484647 | H28: ERODE,743866 | I28: RANCHI | J28: 32FEET SXL | K28: 52820 | L28: 97650 | M28: =Table1[[#This Row],[Billing Rate Charges]]-Table1[[#This Row],[ LORRY RATE ]] -> 44830 | P28: DONE | Q28: 026 | R28: RECEIPT | S28: 23-06-2024 | T28: 23-06-2024 | U28: closed | V28: BN | W28: SPEED MODE MATERIAL EXTRA CHARGE
A29: 29 | B29: JUNE | C29: 45464 | D29: 3rd Party | E29: TN93L-8071 | F29: 9754088991 | G29: RANCHI | H29: NARSAPUR,912069+HOSKOTE,483982 | I29: BOMMANSANDRA,607558 | J29: 32FEET SXL | K29: 33110 | L29: 52920 | M29: =Table1[[#This Row],[Billing Rate Charges]]-Table1[[#This Row],[ LORRY RATE ]] -> 19810 | N29: 33110 | O29: =Table1[[#This Row],[ LORRY RATE ]]-Table1[[#This Row],[Adance Paid (INR)]] -> 0 | P29: DONE | Q29: 027 | R29: RECEIPT | S29: 25-06-2024 | T29: 26-06-2024 | U29: closed | V29: Transporter 02 | W29: MISC NOTE
A30: 30 | B30: JUNE | C30: 45467 | D30: BN | E30: JH01KM-8803 | F30: 9589264337 | G30: RANCHI | H30: HOSKOTE,742750 | I30: HASSAN ,377936 | J30: 32 FEET SXL | K30: 45170 | L30: 46620 | M30: =Table1[[#This Row],[Billing Rate Charges]]-Table1[[#This Row],[ LORRY RATE ]] -> 1450 | O30: 0 | P30: DONE | Q30: 028 | R30: RECEIPT | S30: 27-06-2024 | T30: 27-06-2024 | U30: closed | V30: BN
A31: 31 | B31: JUNE | C31: 45468 | D31: BN | E31: JH01KM-4371 | F31: 9025368773 | G31: HOSUR | H31: N/A | I31: RANCHI,261832 | J31: 24FEET | K31: 48290 | L31: 67410 | M31: =Table1[[#This Row],[Billing Rate Charges]]-Table1[[#This Row],[ LORRY RATE ]] -> 19120 | O31: 0 | P31: DONE | Q31: 029 | R31: RECEIPT | S31: 28-06-2024 | T31: 28-06-2024 | U31: closed | V31: BN
A32: 32 | B32: JUNE | C32: 45469 | D32: 3rd Party | E32: TN52TM-1398 | F32: 9941053951 | G32: RANCHI | H32: N/A | I32: HOSKOTE,491423 | J32: 32FEET SXL | K32: 33890 | L32: 40320 | M32: =Table1[[#This Row],[Billing Rate Charges]]-Table1[[#This Row],[ LORRY RATE ]] -> 6430 | N32: 33890 | O32: =Table1[[#This Row],[ LORRY RATE ]]-Table1[[#This Row],[Adance Paid (INR)]] -> 0 | P32: DONE | Q32: 030 | R32: RECEIPT | S32: 30-06-2024 | T32: 01-07-2024 | U32: closed | V32: Transporter 02
A33: 33 | B33: JUNE | C33: 45470 | D33: 3rd Party | E33: TN18GS-5854 | F33: 9834816284 | G33: RANCHI | H33: N/A | I33: NARSAPUR,366358 | J33: 32FEET SXL | K33: 34840 | L33: 46620 | M33: =Table1[[#This Row],[Billing Rate Charges]]-Table1[[#This Row],[ LORRY RATE ]] -> 11780 | N33: 34840 | O33: =Table1[[#This Row],[ LORRY RATE ]]-Table1[[#This Row],[Adance Paid (INR)]] -> 0 | P33: DONE | Q33: 031 | R33: RECEIPT | S33: 03-07-2024 | T33: 03-07-2024 | U33: closed | V33: Transporter 02 | W33: LORRY HALTING - EXTRA CHARGE
A34: 34 | B34: JULY | C34: 45474 | D34: 3rd Party | E34: GJ27K-9382 | F34: 9660512245 | G34: AHM. | H34: N/A | I34: RANCHI,862761 | J34: 20FEET | K34: 44920 | L34: 56700 | M34: =Table1[[#This Row],[Billing Rate Charges]]-Table1[[#This Row],[ LORRY RATE ]] -> 11780 | N34: 41620 | O34: =Table1[[#This Row],[ LORRY RATE ]]-Table1[[#This Row],[Adance Paid (INR)]] -> 3300 | P34: DONE | Q34: 037 | R34: PENDING | S34: 05-07-2024 | T34: 05-07-2024 | U34: closed | V34: Transporter 04 | W34: MATERIAL SHIFTED TO ANOTHER VEHICLE
A35: 35 | B35: JULY | C35: 45474 | D35: BN | E35: JH01KM-4371 | F35: 9025368773 | G35: RANCHI | H35: HOSKOTE,136530 | I35: HASSAN,323165 | J35: 24FEET | K35: 45740 | L35: 50400 | M35: =Table1[[#This Row],[Billing Rate Charges]]-Table1[[#This Row],[ LORRY RATE ]] -> 4660 | O35: 0 | P35: DONE | Q35: 032 | R35: RECEIPT | S35: 04-07-2024 | T35: 05-07-2024 | U35: closed | V35: BN
A36: 36 | B36: JULY | C36: 45474 | D36: BN | E36: JH01KM-8803 | F36: 9025368773 | G36: TIRUPUR,211792/56 | H36: ERODE,377051 | I36: RANCHI | J36: 32FEET | K36: 53580 | L36: 102690 | M36: =Table1[[#This Row],[Billing Rate Charges]]-Table1[[#This Row],[ LORRY RATE ]] -> 49110 | O36: 0 | P36: DONE | Q36: 033 | R36: RECEIPT | S36: 04-07-2024 | T36: 05-07-2024 | U36: closed | V36: BN
A37: 37 | B37: JULY | C37: 45475 | D37: 3rd Party | E37: KA52W-2643 | F37: 9578386887 | G37: RANCHI | H37: HOSKOTE,042648 | I37: BOMMANSANDRA,693938 | J37: 24FEET | K37: 29180 | L37: 48200 | M37: =Table1[[#This Row],[Billing Rate Charges]]-Table1[[#This Row],[ LORRY RATE ]] -> 19020 | N37: 29180 | O37: =Table1[[#This Row],[ LORRY RATE ]]-Table1[[#This Row],[Adance Paid (INR)]] -> 0 | P37: DONE | Q37: 034 | R37: RECEIPT | S37: 05-07-2024 | T37: 06-07-2024 | U37: closed | V37: Transporter 02 | W37: LORRY HALTING - EXTRA CHARGE
A38: 38 | B38: JULY | C38: 45475 | D38: 3rd Party | E38: TN12XD-6346 | F38: 9678275995 | G38: RANCHI | H38: N/A | I38: NARSAPUR,362044 | J38: 20FEET | K38: 25150 | L38: 35600 | M38: =Table1[[#This Row],[Billing Rate Charges]]-Table1[[#This Row],[ LORRY RATE ]] -> 10450 | N38: 25150 | O38: =Table1[[#This Row],[ LORRY RATE ]]-Table1[[#This Row],[Adance Paid (INR)]] -> 0 | P38: DONE | Q38: 035 | R38: RECEIPT | S38: 09-07-2024 | T38: 09-07-2024 | U38: closed | V38: Transporter 02
A39: 39 | B39: JULY | C39: 45475 | D39: 3rd Party | E39: TN12XD-6346 | F39: 9678275995 | G39: RANCHI | H39: PART LOAD | I39: HOSUR,398331 | J39: 20FEET | K39: 0 | L39: 11500 | M39: =Table1[[#This Row],[Billing Rate Charges]]-Table1[[#This Row],[ LORRY RATE ]] -> 11500 | O39: =Table1[[#This Row],[ LORRY RATE ]]-Table1[[#This Row],[Adance Paid (INR)]] -> 0 | P39: DONE | Q39: 036 | R39: RECEIPT | S39: 09-07-2024 | T39: 09-07-2024 | U39: closed | V39: Transporter 02 | W39: WEIGHT-BASED BILLING (PART LOAD)
A40: 40 | B40: JULY | C40: 45476 | D40: 3rd Party | E40: NL01N-2927 | F40: 9513184912 | G40: RANCHI | H40: NARSAPUR,199550 | I40: BOMMANSANDRA, 387363 | J40: 32 FEET SXL | K40: 35310 | L40: 49770 | M40: =Table1[[#This Row],[Billing Rate Charges]]-Table1[[#This Row],[ LORRY RATE ]] -> 14460 | N40: 35310 | O40: =Table1[[#This Row],[ LORRY RATE ]]-Table1[[#This Row],[Adance Paid (INR)]] -> 0 | P40: DONE | Q40: 038 | R40: RECEIPT | S40: 09-07-2024 | T40: 10-07-2024 | U40: closed | V40: Transporter 05 | W40: LORRY HALTING - EXTRA CHARGE
...

Sheet AUBURN LOAD CLEAN
A1: AUBURN LOAD REGISTER — BN LOGISTICS
A2: LOADS | B2: =SUMPRODUCT(--(AUBURN[LOADING DATE]<>"")) -> 1114 | D2: LORRY RATE PAID | E2: =SUM(AUBURN[LORRY RATE (₹)]) -> 45985070 | G2: MARGIN % | H2: =IFERROR($E$4/$E$3,"") -> 0.39240619 | J2: OWN FLEET (BN) LOADS | K2: =COUNTIF(AUBURN[PROVIDER],"BN") -> 684 | M2: Blue = you type it
A3: PERIOD | B3: =TEXT(MIN(AUBURN[LOADING DATE]),"mmm yyyy")&" to "&TEXT(MAX(AUBURN[LOADING DATE]),"mmm yyyy") -> May 2024 to Sep 2026 | D3: BILLED TO AUBURN | E3: =SUM(AUBURN[BILLING RATE (₹)]) -> 75694270 | G3: ADVANCE PAID | H3: =SUM(AUBURN[ADVANCE PAID (₹)]) -> 43905850 | J3: 3RD PARTY LOADS | K3: =COUNTIF(AUBURN[PROVIDER],"3rd Party") -> 430 | M3: Black = calculated, do not type
A4: AVG TRANSIT DAYS | B4: =IFERROR(AVERAGE(AUBURN[TRANSIT DAYS]),"") -> 3.8969754 | D4: NET SAVING | E4: =SUM(AUBURN[NET SAVING (₹)]) -> 29702900 | G4: BALANCE TO PAY | H4: =SUM(AUBURN[BALANCE TO PAY (₹)]) -> 118940 | J4: NO ADVANCE LOGGED | K4: =COUNTIF(AUBURN[LORRY RATE (₹)],">0")-SUMPRODUCT((AUBURN[LORRY RATE (₹)]>0)*(AUBURN[ADVANCE PAID (₹)]<>"")) -> 41 | M4: AA:AB (grouped) keep the original date text for traceability
A6: S.NO. | B6: LOADING DATE | C6: MONTH | D6: PROVIDER | E6: LORRY NO. | F6: MOBILE NO. | G6: FROM | H6: POINT GR NO. | I6: TO GR NO. | J6: LORRY MAKE | K6: LORRY RATE (₹) | L6: BILLING RATE (₹) | M6: NET SAVING (₹) | N6: MARGIN % | O6: ADVANCE PAID (₹) | P6: BALANCE TO PAY (₹) | Q6: BILL STATUS | R6: INVOICE NO. | S6: PAYMENT STATUS | T6: REACH DATE | U6: UNLOAD DATE | V6: UNLOAD END | W6: TRANSIT DAYS | X6: CURRENT STATUS | Y6: BROKER ADDRESS | Z6: REMARKS | AA6: REACH AS LOGGED | AB6: UNLOAD AS LOGGED
A7: =IF($B7="","",ROW()-6) -> 1 | B7: 45422 | C7: =IF($B7="","",EOMONTH($B7,-1)+1) -> 45413 | D7: 3rd Party | E7: TN52TM-7760 | F7: 9686844715 | G7: RANCHI | H7: HASSAN.176610,BOX 04 | I7: BOMMANSA.562608,BOX 578 | J7: 32FEET SXL | K7: 38590 | L7: 46620 | M7: =IF(OR($K7="",$L7=""),"",$L7-$K7) -> 8030 | N7: =IF(OR($L7="",$L7=0,$M7=""),"",$M7/$L7) -> 0.17224367 | O7: 38590 | P7: =IF(OR($K7="",$O7=""),"",$K7-$O7) -> 0 | Q7: DONE | R7: 1 | S7: RECEIPT | T7: 45422 | U7: 45427 | V7: 45430 | W7: =IF(OR($B7="",$U7=""),"",$U7-$B7) -> 5 | X7: Closed | Y7: Transporter 01 | AA7: SAME DAY | AB7: 15/05/2024./18/05/2024
A8: =IF($B8="","",ROW()-6) -> 2 | B8: 45427 | C8: =IF($B8="","",EOMONTH($B8,-1)+1) -> 45413 | D8: 3rd Party | E8: TN52TM-1398 | F8: 9941053951 | G8: RANCHI | H8: HOSKOTE.749378,BOX 983 | I8: HASSAN,772300,BOX 004 | J8: 32FEET SXL | K8: 36450 | L8: 46620 | M8: =IF(OR($K8="",$L8=""),"",$L8-$K8) -> 10170 | N8: =IF(OR($L8="",$L8=0,$M8=""),"",$M8/$L8) -> 0.21814672 | O8: 36450 | P8: =IF(OR($K8="",$O8=""),"",$K8-$O8) -> 0 | Q8: DONE | R8: 2 | S8: RECEIPT | T8: 45431 | U8: 45432 | V8: 45434 | W8: =IF(OR($B8="",$U8=""),"",$U8-$B8) -> 5 | X8: Closed | Y8: Transporter 02 | AB8: 20/05/2024./22/05/2024
A9: =IF($B9="","",ROW()-6) -> 3 | B9: 45431 | C9: =IF($B9="","",EOMONTH($B9,-1)+1) -> 45413 | D9: 3rd Party | E9: KA05TT-6944 | F9: 9295512602 | G9: RANCHI | H9: NARSAPUR.043922.BOX | I9: HASSAN,978172.BOX | J9: 24FEET | K9: 31930 | L9: 45040 | M9: =IF(OR($K9="",$L9=""),"",$L9-$K9) -> 13110 | N9: =IF(OR($L9="",$L9=0,$M9=""),"",$M9/$L9) -> 0.2910746 | O9: 31930 | P9: =IF(OR($K9="",$O9=""),"",$K9-$O9) -> 0 | Q9: DONE | R9: 3 | S9: RECEIPT | T9: 45433 | U9: 45433 | V9: 45434 | W9: =IF(OR($B9="",$U9=""),"",$U9-$B9) -> 2 | X9: Closed | Y9: Transporter 02 | AB9: 21/05/2024./22/05/2024
A10: =IF($B10="","",ROW()-6) -> 4 | B10: 45430 | C10: =IF($B10="","",EOMONTH($B10,-1)+1) -> 45413 | D10: 3rd Party | E10: KA02GM-9724 | F10: 9149905009 | G10: RANCHI | H10: N/A | I10: HASSAN.909686.BOX 312 | J10: 22FEET | K10: 28300 | L10: 38740 | M10: =IF(OR($K10="",$L10=""),"",$L10-$K10) -> 10440 | N10: =IF(OR($L10="",$L10=0,$M10=""),"",$M10/$L10) -> 0.2694889 | O10: 28300 | P10: =IF(OR($K10="",$O10=""),"",$K10-$O10) -> 0 | Q10: DONE | R10: 4 | S10: RECEIPT | T10: 45433 | U10: 45433 | W10: =IF(OR($B10="",$U10=""),"",$U10-$B10) -> 3 | X10: Closed | Y10: Transporter 02
A11: =IF($B11="","",ROW()-6) -> 5 | B11: 45431 | C11: =IF($B11="","",EOMONTH($B11,-1)+1) -> 45413 | D11: 3rd Party | E11: TN12RW-1972 | F11: 9678275995 | G11: RANCHI | H11: N/A | I11: HOSKOTE.125550.BOX 729 | J11: 20FEET | K11: 27830 | L11: 35600 | M11: =IF(OR($K11="",$L11=""),"",$L11-$K11) -> 7770 | N11: =IF(OR($L11="",$L11=0,$M11=""),"",$M11/$L11) -> 0.21825843 | O11: 27830 | P11: =IF(OR($K11="",$O11=""),"",$K11-$O11) -> 0 | Q11: DONE | R11: 5 | S11: RECEIPT | T11: 45433 | U11: 45433 | W11: =IF(OR($B11="",$U11=""),"",$U11-$B11) -> 2 | X11: Closed | Y11: Transporter 02
A12: =IF($B12="","",ROW()-6) -> 6 | B12: 45436 | C12: =IF($B12="","",EOMONTH($B12,-1)+1) -> 45413 | D12: 3rd Party | E12: KA51DJ-2589 | F12: 9087547668 | G12: RANCHI | H12: NARSAPUR,803363 | I12: HOSKOTE,467212 | J12: 20FEET | K12: 29850 | L12: 41900 | M12: =IF(OR($K12="",$L12=""),"",$L12-$K12) -> 12050 | N12: =IF(OR($L12="",$L12=0,$M12=""),"",$M12/$L12) -> 0.2875895 | O12: 29850 | P12: =IF(OR($K12="",$O12=""),"",$K12-$O12) -> 0 | Q12: DONE | R12: 6 | S12: RECEIPT | T12: 45440 | U12: 45440 | W12: =IF(OR($B12="",$U12=""),"",$U12-$B12) -> 4 | X12: Closed | Y12: Transporter 02
A13: =IF($B13="","",ROW()-6) -> 7 | B13: 45442 | C13: =IF($B13="","",EOMONTH($B13,-1)+1) -> 45413 | D13: 3rd Party | E13: PB13MM-3286 | F13: 9757815238 | G13: RANCHI | H13: N/A | I13: HOKOTE,579908 | J13: 32FEET SXL | K13: 32290 | L13: 40320 | M13: =IF(OR($K13="",$L13=""),"",$L13-$K13) -> 8030 | N13: =IF(OR($L13="",$L13=0,$M13=""),"",$M13/$L13) -> 0.19915675 | O13: 32290 | P13: =IF(OR($K13="",$O13=""),"",$K13-$O13) -> 0 | Q13: DONE | R13: 7 | S13: RECEIPT | T13: 45417 | U13: 45417 | W13: =IF(OR($B13="",$U13=""),"",$U13-$B13) -> -25 | X13: Closed | Y13: Transporter 01
A14: =IF($B14="","",ROW()-6) -> 8 | B14: 45436 | C14: =IF($B14="","",EOMONTH($B14,-1)+1) -> 45413 | D14: BN | E14: JH01KM-4371 | F14: 9025368773 | G14: RANCHI | H14: N/A | I14: HOSKOTE,749252 | J14: 24FEET SXL | K14: 43990 | L14: 38740 | M14: =IF(OR($K14="",$L14=""),"",$L14-$K14) -> -5250 | N14: =IF(OR($L14="",$L14=0,$M14=""),"",$M14/$L14) -> -0.13551884 | P14: =IF(OR($K14="",$O14=""),"",$K14-$O14) | Q14: DONE | R14: 8 | S14: RECEIPT | T14: 45439 | U14: 45440 | W14: =IF(OR($B14="",$U14=""),"",$U14-$B14) -> 4 | X14: Closed | Y14: BN
A15: =IF($B15="","",ROW()-6) -> 9 | B15: 45440 | C15: =IF($B15="","",EOMONTH($B15,-1)+1) -> 45413 | D15: BN | E15: JH01KM-4371 | F15: 9025368773 | G15: HOSKOTE | H15: BOMMANHALLI | I15: DODABALLAPUR | J15: 24FEET SXL | L15: 6300 | M15: =IF(OR($K15="",$L15=""),"",$L15-$K15) | N15: =IF(OR($L15="",$L15=0,$M15=""),"",$M15/$L15) | P15: =IF(OR($K15="",$O15=""),"",$K15-$O15) | Q15: DONE | R15: 9 | S15: RECEIPT | W15: =IF(OR($B15="",$U15=""),"",$U15-$B15) | X15: Closed | Y15: BN | AA15: LOADING
A16: =IF($B16="","",ROW()-6) -> 10 | B16: 45442 | C16: =IF($B16="","",EOMONTH($B16,-1)+1) -> 45413 | D16: BN | E16: JH01KM-4371 | F16: 9025368773 | G16: DODABALLAPUR | H16: N/A | I16: RANCHI ,872415/27 | J16: 24FEET SXL | K16: 48290 | L16: 67410 | M16: =IF(OR($K16="",$L16=""),"",$L16-$K16) -> 19120 | N16: =IF(OR($L16="",$L16=0,$M16=""),"",$M16/$L16) -> 0.28363744 | P16: =IF(OR($K16="",$O16=""),"",$K16-$O16) | Q16: DONE | R16: 9 | S16: RECEIPT | T16: 45445 | U16: 45446 | W16: =IF(OR($B16="",$U16=""),"",$U16-$B16) -> 4 | X16: Closed | Y16: BN
A17: =IF($B17="","",ROW()-6) -> 11 | B17: 45436 | C17: =IF($B17="","",EOMONTH($B17,-1)+1) -> 45413 | D17: BN | E17: JH01KM-8803 | F17: 9589264337 | G17: RANCHI | H17: N/A | I17: HOSKOTE ,140915 | J17: 32FEET SXL | K17: 44220 | L17: 40320 | M17: =IF(OR($K17="",$L17=""),"",$L17-$K17) -> -3900 | N17: =IF(OR($L17="",$L17=0,$M17=""),"",$M17/$L17) -> -0.09672619 | P17: =IF(OR($K17="",$O17=""),"",$K17-$O17) | Q17: DONE | R17: 10 | S17: RECEIPT | T17: 45439 | U17: 45439 | W17: =IF(OR($B17="",$U17=""),"",$U17-$B17) -> 3 | X17: Closed | Y17: BN
A18: =IF($B18="","",ROW()-6) -> 12 | B18: 45439 | C18: =IF($B18="","",EOMONTH($B18,-1)+1) -> 45413 | D18: BN | E18: JH01KM-8803 | F18: 9589264337 | G18: TIRUPUR | H18: N/A | I18: RANCHI,407449 | J18: 32FEET SXL | K18: 51030 | L18: 85680 | M18: =IF(OR($K18="",$L18=""),"",$L18-$K18) -> 34650 | N18: =IF(OR($L18="",$L18=0,$M18=""),"",$M18/$L18) -> 0.40441176 | P18: =IF(OR($K18="",$O18=""),"",$K18-$O18) | Q18: DONE | R18: 11 | S18: RECEIPT | T18: 45443 | U18: 45443 | W18: =IF(OR($B18="",$U18=""),"",$U18-$B18) -> 4 | X18: Closed | Y18: BN
A19: =IF($B19="","",ROW()-6) -> 13 | B19: 45444 | C19: =IF($B19="","",EOMONTH($B19,-1)+1) -> 45444 | D19: 3rd Party | E19: KA02YH-5646 | F19: 9198923795 | G19: RANCHI | H19: N/A | I19: HOSKOTE,264810 | J19: 20FEET | K19: 27290 | L19: 35600 | M19: =IF(OR($K19="",$L19=""),"",$L19-$K19) -> 8310 | N19: =IF(OR($L19="",$L19=0,$M19=""),"",$M19/$L19) -> 0.23342697 | O19: 27290 | P19: =IF(OR($K19="",$O19=""),"",$K19-$O19) -> 0 | Q19: DONE | R19: 12 | S19: RECEIPT | T19: 45447 | U19: 45447 | W19: =IF(OR($B19="",$U19=""),"",$U19-$B19) -> 3 | X19: Closed | Y19: Transporter 02
A20: =IF($B20="","",ROW()-6) -> 14 | B20: 45444 | C20: =IF($B20="","",EOMONTH($B20,-1)+1) -> 45444 | D20: 3rd Party | E20: KA05RX-6944 | F20: 9295512602 | G20: RANCHI | H20: N/A | I20: HASSAN,872860 | J20: 24FEET | K20: 29110 | L20: 38740 | M20: =IF(OR($K20="",$L20=""),"",$L20-$K20) -> 9630 | N20: =IF(OR($L20="",$L20=0,$M20=""),"",$M20/$L20) -> 0.24858028 | O20: 29110 | P20: =IF(OR($K20="",$O20=""),"",$K20-$O20) -> 0 | Q20: DONE | R20: 13 | S20: RECEIPT | T20: 45447 | U20: 45447 | W20: =IF(OR($B20="",$U20=""),"",$U20-$B20) -> 3 | X20: Closed | Y20: Transporter 02
A21: =IF($B21="","",ROW()-6) -> 15 | B21: 45444 | C21: =IF($B21="","",EOMONTH($B21,-1)+1) -> 45444 | D21: BN | E21: JH01KM-8803 | F21: 9589264337 | G21: RANCHI | H21: N/A | I21: HASSAN,913653 | J21: 32FEET SXL | K21: 44220 | L21: 40320 | M21: =IF(OR($K21="",$L21=""),"",$L21-$K21) -> -3900 | N21: =IF(OR($L21="",$L21=0,$M21=""),"",$M21/$L21) -> -0.09672619 | P21: =IF(OR($K21="",$O21=""),"",$K21-$O21) | Q21: DONE | R21: 14 | S21: RECEIPT | T21: 45448 | U21: 45448 | W21: =IF(OR($B21="",$U21=""),"",$U21-$B21) -> 4 | X21: Closed | Y21: BN
A22: =IF($B22="","",ROW()-6) -> 16 | B22: 45446 | C22: =IF($B22="","",EOMONTH($B22,-1)+1) -> 45444 | D22: BN | E22: JH01KM-4371 | F22: 9025368773 | G22: RANCHI | H22: NARSAPUR,970325+HOSKOTE,425534 | I22: BOMMANSANDRA ,890248 | J22: 24 FEET SXL | K22: 45880 | L22: 51340 | M22: =IF(OR($K22="",$L22=""),"",$L22-$K22) -> 5460 | N22: =IF(OR($L22="",$L22=0,$M22=""),"",$M22/$L22) -> 0.10634982 | P22: =IF(OR($K22="",$O22=""),"",$K22-$O22) | Q22: DONE | R22: 15 | S22: RECEIPT | T22: 45449 | U22: 45450 | W22: =IF(OR($B22="",$U22=""),"",$U22-$B22) -> 4 | X22: Closed | Y22: BN
A23: =IF($B23="","",ROW()-6) -> 17 | B23: 45449 | C23: =IF($B23="","",EOMONTH($B23,-1)+1) -> 45444 | D23: BN | E23: JH01KM8803 | F23: 9589264337 | G23: TIRUPUR | H23: N/A | I23: RANCHI,476477 | J23: 32 FEET SXL | K23: 51690 | L23: 90090 | M23: =IF(OR($K23="",$L23=""),"",$L23-$K23) -> 38400 | N23: =IF(OR($L23="",$L23=0,$M23=""),"",$M23/$L23) -> 0.42624043 | P23: =IF(OR($K23="",$O23=""),"",$K23-$O23) | Q23: DONE | R23: 16 | S23: RECEIPT | T23: 45452 | U23: 45453 | W23: =IF(OR($B23="",$U23=""),"",$U23-$B23) -> 4 | X23: Closed | Y23: BN
A24: =IF($B24="","",ROW()-6) -> 18 | B24: 45450 | C24: =IF($B24="","",EOMONTH($B24,-1)+1) -> 45444 | D24: 3rd Party | E24: KA02GM-9724 | F24: 9149905009 | G24: RANCHI | H24: BOMMANSANDRA,933942 | I24: HOSKOTE,387835 | J24: 22FEET | K24: 27640 | L24: 45040 | M24: =IF(OR($K24="",$L24=""),"",$L24-$K24) -> 17400 | N24: =IF(OR($L24="",$L24=0,$M24=""),"",$M24/$L24) -> 0.38632327 | O24: 27640 | P24: =IF(OR($K24="",$O24=""),"",$K24-$O24) -> 0 | Q24: DONE | R24: 17 | S24: RECEIPT | T24: 45454 | U24: 45454 | W24: =IF(OR($B24="",$U24=""),"",$U24-$B24) -> 4 | X24: Closed | Y24: Transporter 02
A25: =IF($B25="","",ROW()-6) -> 19 | B25: 45450 | C25: =IF($B25="","",EOMONTH($B25,-1)+1) -> 45444 | D25: BN | E25: JH01KM-4371 | F25: 9025368773 | G25: ERODE | H25: N/A | I25: RANCHI,187030 | J25: 24FEET | K25: 48290 | L25: 67410 | M25: =IF(OR($K25="",$L25=""),"",$L25-$K25) -> 19120 | N25: =IF(OR($L25="",$L25=0,$M25=""),"",$M25/$L25) -> 0.28363744 | P25: =IF(OR($K25="",$O25=""),"",$K25-$O25) | Q25: DONE | R25: 18 | S25: RECEIPT | T25: 45452 | U25: 45453 | W25: =IF(OR($B25="",$U25=""),"",$U25-$B25) -> 3 | X25: Closed | Y25: BN
A26: =IF($B26="","",ROW()-6) -> 20 | B26: 45455 | C26: =IF($B26="","",EOMONTH($B26,-1)+1) -> 45444 | D26: BN | E26: JH01KM-4371 | F26: 9025368773 | G26: RANCHI | H26: HOSKOTE,900316 | I26: BOMMANSA,863494 | J26: 24FEET | K26: 44930 | L26: 45040 | M26: =IF(OR($K26="",$L26=""),"",$L26-$K26) -> 110 | N26: =IF(OR($L26="",$L26=0,$M26=""),"",$M26/$L26) -> 0.0024422735 | P26: =IF(OR($K26="",$O26=""),"",$K26-$O26) | Q26: DONE | R26: 19 | S26: RECEIPT | T26: 45458 | U26: 45458 | W26: =IF(OR($B26="",$U26=""),"",$U26-$B26) -> 3 | X26: Closed | Y26: BN
A27: =IF($B27="","",ROW()-6) -> 21 | B27: 45456 | C27: =IF($B27="","",EOMONTH($B27,-1)+1) -> 45444 | D27: BN | E27: JH01KM-8803 | F27: 9589264337 | G27: RANCHI | H27: NARSAPUR,763576 | I27: BOMMANSANDRA,516517 | J27: 32FEET SXL | K27: 45170 | L27: 46620 | M27: =IF(OR($K27="",$L27=""),"",$L27-$K27) -> 1450 | N27: =IF(OR($L27="",$L27=0,$M27=""),"",$M27/$L27) -> 0.031102531 | P27: =IF(OR($K27="",$O27=""),"",$K27-$O27) | Q27: DONE | R27: 20 | S27: RECEIPT | T27: 45459 | U27: 45462 | W27: =IF(OR($B27="",$U27=""),"",$U27-$B27) -> 6 | X27: Closed | Y27: BN | Z27: LORRY HALTING - EXTRA CHARGE
A28: =IF($B28="","",ROW()-6) -> 22 | B28: 45457 | C28: =IF($B28="","",EOMONTH($B28,-1)+1) -> 45444 | D28: 3rd Party | E28: WB23J-3143 | F28: 9372267009 | G28: ERODE | H28: N/A | I28: RANCHI,241257 | J28: 32FEET MXL | K28: 75570 | L28: 93240 | M28: =IF(OR($K28="",$L28=""),"",$L28-$K28) -> 17670 | N28: =IF(OR($L28="",$L28=0,$M28=""),"",$M28/$L28) -> 0.18951094 | O28: 75570 | P28: =IF(OR($K28="",$O28=""),"",$K28-$O28) -> 0 | Q28: DONE | R28: 21 | S28: RECEIPT | T28: 45462 | U28: 45462 | W28: =IF(OR($B28="",$U28=""),"",$U28-$B28) -> 5 | X28: Closed | Y28: Transporter 03 | AA28: 19-06-2024 | AB28: 19-06-2024
A29: =IF($B29="","",ROW()-6) -> 23 | B29: 45458 | C29: =IF($B29="","",EOMONTH($B29,-1)+1) -> 45444 | D29: 3rd Party | E29: KA05TT-6944 | F29: 9295512602 | G29: RANCHI | H29: N/A | I29: HASSAN,857821 | J29: 24FEET | K29: 27770 | L29: 38740 | M29: =IF(OR($K29="",$L29=""),"",$L29-$K29) -> 10970 | N29: =IF(OR($L29="",$L29=0,$M29=""),"",$M29/$L29) -> 0.28316985 | O29: 27770 | P29: =IF(OR($K29="",$O29=""),"",$K29-$O29) -> 0 | Q29: DONE | R29: 22 | S29: RECEIPT | T29: 45462 | U29: 45462 | W29: =IF(OR($B29="",$U29=""),"",$U29-$B29) -> 4 | X29: Closed | Y29: Transporter 02 | AA29: 19-06-2024 | AB29: 19-06-2024
A30: =IF($B30="","",ROW()-6) -> 24 | B30: 45459 | C30: =IF($B30="","",EOMONTH($B30,-1)+1) -> 45444 | D30: BN | E30: JH01KM-4371 | F30: 9025368773 | G30: ERODE | H30: N/A | I30: RANCHI,454688 | J30: 24FEET | K30: 48290 | L30: 67410 | M30: =IF(OR($K30="",$L30=""),"",$L30-$K30) -> 19120 | N30: =IF(OR($L30="",$L30=0,$M30=""),"",$M30/$L30) -> 0.28363744 | P30: =IF(OR($K30="",$O30=""),"",$K30-$O30) | Q30: DONE | R30: 23 | S30: RECEIPT | T30: 45461 | U30: 45461 | W30: =IF(OR($B30="",$U30=""),"",$U30-$B30) -> 2 | X30: Closed | Y30: BN | Z30: OVERLOAD - EXTRA CHARGE | AA30: 18-06-2024 | AB30: 18-06-2024
A31: =IF($B31="","",ROW()-6) -> 25 | B31: 45460 | C31: =IF($B31="","",EOMONTH($B31,-1)+1) -> 45444 | D31: 3rd Party | E31: KA53T-7407 | F31: 9684865656 | G31: RANCHI | H31: NARSAPUR,795057 | I31: HASSAN,857821 | J31: 20FEET | K31: 26100 | L31: 41900 | M31: =IF(OR($K31="",$L31=""),"",$L31-$K31) -> 15800 | N31: =IF(OR($L31="",$L31=0,$M31=""),"",$M31/$L31) -> 0.37708831 | O31: 26100 | P31: =IF(OR($K31="",$O31=""),"",$K31-$O31) -> 0 | Q31: DONE | R31: 25 | S31: RECEIPT | T31: 45464 | U31: 45465 | W31: =IF(OR($B31="",$U31=""),"",$U31-$B31) -> 5 | X31: Closed | Y31: Transporter 02 | AA31: 21-06-2024 | AB31: 22-06-2024
A32: =IF($B32="","",ROW()-6) -> 26 | B32: 45462 | C32: =IF($B32="","",EOMONTH($B32,-1)+1) -> 45444 | D32: BN | E32: JH01KM-4371 | F32: 9025368773 | G32: RANCHI | H32: N/A | I32: HASSAN,493930 | J32: 24FEET | K32: 46520 | L32: 55600 | M32: =IF(OR($K32="",$L32=""),"",$L32-$K32) -> 9080 | N32: =IF(OR($L32="",$L32=0,$M32=""),"",$M32/$L32) -> 0.16330935 | P32: =IF(OR($K32="",$O32=""),"",$K32-$O32) | Q32: DONE | R32: 24 | S32: RECEIPT | T32: 45465 | U32: 45465 | W32: =IF(OR($B32="",$U32=""),"",$U32-$B32) -> 3 | X32: Closed | Y32: BN | AA32: 22-06-2024 | AB32: 22-06-2024
A33: =IF($B33="","",ROW()-6) -> 27 | B33: 45463 | C33: =IF($B33="","",EOMONTH($B33,-1)+1) -> 45444 | D33: BN | E33: JH01KM-8803 | F33: 9589264337 | G33: TIRUPUR,484647 | H33: ERODE,743866 | I33: RANCHI | J33: 32FEET SXL | K33: 52820 | L33: 97650 | M33: =IF(OR($K33="",$L33=""),"",$L33-$K33) -> 44830 | N33: =IF(OR($L33="",$L33=0,$M33=""),"",$M33/$L33) -> 0.45908858 | P33: =IF(OR($K33="",$O33=""),"",$K33-$O33) | Q33: DONE | R33: 26 | S33: RECEIPT | T33: 45466 | U33: 45466 | W33: =IF(OR($B33="",$U33=""),"",$U33-$B33) -> 3 | X33: Closed | Y33: BN | Z33: SPEED MODE MATERIAL EXTRA CHARGE | AA33: 23-06-2024 | AB33: 23-06-2024
A34: =IF($B34="","",ROW()-6) -> 28 | B34: 45464 | C34: =IF($B34="","",EOMONTH($B34,-1)+1) -> 45444 | D34: 3rd Party | E34: TN93L-8071 | F34: 9754088991 | G34: RANCHI | H34: NARSAPUR,912069+HOSKOTE,483982 | I34: BOMMANSANDRA,607558 | J34: 32FEET SXL | K34: 33110 | L34: 52920 | M34: =IF(OR($K34="",$L34=""),"",$L34-$K34) -> 19810 | N34: =IF(OR($L34="",$L34=0,$M34=""),"",$M34/$L34) -> 0.37433862 | O34: 33110 | P34: =IF(OR($K34="",$O34=""),"",$K34-$O34) -> 0 | Q34: DONE | R34: 27 | S34: RECEIPT | T34: 45468 | U34: 45469 | W34: =IF(OR($B34="",$U34=""),"",$U34-$B34) -> 5 | X34: Closed | Y34: Transporter 02 | Z34: MISC NOTE | AA34: 25-06-2024 | AB34: 26-06-2024
A35: =IF($B35="","",ROW()-6) -> 29 | B35: 45467 | C35: =IF($B35="","",EOMONTH($B35,-1)+1) -> 45444 | D35: BN | E35: JH01KM-8803 | F35: 9589264337 | G35: RANCHI | H35: HOSKOTE,742750 | I35: HASSAN ,377936 | J35: 32 FEET SXL | K35: 45170 | L35: 46620 | M35: =IF(OR($K35="",$L35=""),"",$L35-$K35) -> 1450 | N35: =IF(OR($L35="",$L35=0,$M35=""),"",$M35/$L35) -> 0.031102531 | P35: =IF(OR($K35="",$O35=""),"",$K35-$O35) | Q35: DONE | R35: 28 | S35: RECEIPT | T35: 45470 | U35: 45470 | W35: =IF(OR($B35="",$U35=""),"",$U35-$B35) -> 3 | X35: Closed | Y35: BN | AA35: 27-06-2024 | AB35: 27-06-2024
A36: =IF($B36="","",ROW()-6) -> 30 | B36: 45468 | C36: =IF($B36="","",EOMONTH($B36,-1)+1) -> 45444 | D36: BN | E36: JH01KM-4371 | F36: 9025368773 | G36: HOSUR | H36: N/A | I36: RANCHI,261832 | J36: 24FEET | K36: 48290 | L36: 67410 | M36: =IF(OR($K36="",$L36=""),"",$L36-$K36) -> 19120 | N36: =IF(OR($L36="",$L36=0,$M36=""),"",$M36/$L36) -> 0.28363744 | P36: =IF(OR($K36="",$O36=""),"",$K36-$O36) | Q36: DONE | R36: 29 | S36: RECEIPT | T36: 45471 | U36: 45471 | W36: =IF(OR($B36="",$U36=""),"",$U36-$B36) -> 3 | X36: Closed | Y36: BN | AA36: 28-06-2024 | AB36: 28-06-2024
A37: =IF($B37="","",ROW()-6) -> 31 | B37: 45469 | C37: =IF($B37="","",EOMONTH($B37,-1)+1) -> 45444 | D37: 3rd Party | E37: TN52TM-1398 | F37: 9941053951 | G37: RANCHI | H37: N/A | I37: HOSKOTE,491423 | J37: 32FEET SXL | K37: 33890 | L37: 40320 | M37: =IF(OR($K37="",$L37=""),"",$L37-$K37) -> 6430 | N37: =IF(OR($L37="",$L37=0,$M37=""),"",$M37/$L37) -> 0.15947421 | O37: 33890 | P37: =IF(OR($K37="",$O37=""),"",$K37-$O37) -> 0 | Q37: DONE | R37: 30 | S37: RECEIPT | T37: 45473 | U37: 45474 | W37: =IF(OR($B37="",$U37=""),"",$U37-$B37) -> 5 | X37: Closed | Y37: Transporter 02 | AA37: 30-06-2024 | AB37: 45298
A38: =IF($B38="","",ROW()-6) -> 32 | B38: 45470 | C38: =IF($B38="","",EOMONTH($B38,-1)+1) -> 45444 | D38: 3rd Party | E38: TN18GS-5854 | F38: 9834816284 | G38: RANCHI | H38: N/A | I38: NARSAPUR,366358 | J38: 32FEET SXL | K38: 34840 | L38: 46620 | M38: =IF(OR($K38="",$L38=""),"",$L38-$K38) -> 11780 | N38: =IF(OR($L38="",$L38=0,$M38=""),"",$M38/$L38) -> 0.25268125 | O38: 34840 | P38: =IF(OR($K38="",$O38=""),"",$K38-$O38) -> 0 | Q38: DONE | R38: 31 | S38: RECEIPT | T38: 45476 | U38: 45476 | W38: =IF(OR($B38="",$U38=""),"",$U38-$B38) -> 6 | X38: Closed | Y38: Transporter 02 | Z38: LORRY HALTING - EXTRA CHARGE | AA38: 45358 | AB38: 45358
A39: =IF($B39="","",ROW()-6) -> 33 | B39: 45474 | C39: =IF($B39="","",EOMONTH($B39,-1)+1) -> 45474 | D39: 3rd Party | E39: GJ27K-9382 | F39: 9660512245 | G39: AHM. | H39: N/A | I39: RANCHI,862761 | J39: 20FEET | K39: 44920 | L39: 56700 | M39: =IF(OR($K39="",$L39=""),"",$L39-$K39) -> 11780 | N39: =IF(OR($L39="",$L39=0,$M39=""),"",$M39/$L39) -> 0.20776014 | O39: 41620 | P39: =IF(OR($K39="",$O39=""),"",$K39-$O39) -> 3300 | Q39: DONE | R39: 37 | S39: PENDING | T39: 45478 | U39: 45478 | W39: =IF(OR($B39="",$U39=""),"",$U39-$B39) -> 4 | X39: Closed | Y39: Transporter 04 | Z39: MATERIAL SHIFTED TO ANOTHER VEHICLE | AA39: 45419 | AB39: 45419
A40: =IF($B40="","",ROW()-6) -> 34 | B40: 45474 | C40: =IF($B40="","",EOMONTH($B40,-1)+1) -> 45474 | D40: BN | E40: JH01KM-4371 | F40: 9025368773 | G40: RANCHI | H40: HOSKOTE,136530 | I40: HASSAN,323165 | J40: 24FEET | K40: 45740 | L40: 50400 | M40: =IF(OR($K40="",$L40=""),"",$L40-$K40) -> 4660 | N40: =IF(OR($L40="",$L40=0,$M40=""),"",$M40/$L40) -> 0.092460317 | P40: =IF(OR($K40="",$O40=""),"",$K40-$O40) | Q40: DONE | R40: 32 | S40: RECEIPT | T40: 45477 | U40: 45478 | W40: =IF(OR($B40="",$U40=""),"",$U40-$B40) -> 4 | X40: Closed | Y40: BN | AA40: 45389 | AB40: 45419
A41: =IF($B41="","",ROW()-6) -> 35 | B41: 45474 | C41: =IF($B41="","",EOMONTH($B41,-1)+1) -> 45474 | D41: BN | E41: JH01KM-8803 | F41: 9025368773 | G41: TIRUPUR,211792/56 | H41: ERODE,377051 | I41: RANCHI | J41: 32FEET | K41: 53580 | L41: 102690 | M41: =IF(OR($K41="",$L41=""),"",$L41-$K41) -> 49110 | N41: =IF(OR($L41="",$L41=0,$M41=""),"",$M41/$L41) -> 0.47823547 | P41: =IF(OR($K41="",$O41=""),"",$K41-$O41) | Q41: DONE | R41: 33 | S41: RECEIPT | T41: 45477 | U41: 45478 | W41: =IF(OR($B41="",$U41=""),"",$U41-$B41) -> 4 | X41: Closed | Y41: BN | AA41: 45389 | AB41: 45419
...

Sheet Market Load
A1: S.NO. | B1: LOAD DATE | C1: LORRY NO. | D1: CUSTOMER NAME | E1: LOAD FROM | F1: DELIVERY POINT | G1: RATE | H1: ADVANCE | I1: BALANCE | J1: ADVANCE RECEIVED DATE | K1: REMARKS | L1: POD STATUS
A2: 1 | B2: 45756 | C2: JH01KD-6142 | D2: Customer 01 | E2: KRISHNAGIRI | F2: RANCHI | G2: 54450 | H2: 54450 | J2: 45761 | K2: ALL FREIGHT CLEAR NO DUES | L2: DONE
A3: 2 | B3: 45765 | C3: JH01KD-0526 | D3: Customer 02 | E3: HOSKOTE | F3: KOLKATA | G3: 49500 | H3: 49500 | J3: 45768 | K3: ALL FREIGHT CLEAR NO DUES | L3: DONE
A4: 3 | B4: 45768 | C4: JH01KD-2417 | D4: Customer 02 | E4: MALUR | F4: BIHAR SHARIF | G4: 57420 | H4: 57420 | J4: 45772 | K4: ALL FREIGHT CLEAR NO DUES | L4: DONE
A5: 4 | B5: 45772 | C5: JH01KD-6142 | D5: Customer 01 | E5: KRISHNAGIRI | F5: DHULAGARH | G5: 49500 | H5: 49500 | J5: 45776 | K5: ALL FREIGHT CLEAR NO DUES | L5: DONE
A6: 5 | B6: 45772 | C6: JH01KD-0526 | D6: Customer 01 | E6: HOSKOTE | F6: DHULAGARH | G6: 49830 | H6: 49830 | J6: 45778 | K6: ALL FREIGHT CLEAR NO DUES | L6: DONE
A7: 6 | B7: 45773 | C7: JH01KM-8803 | D7: Customer 02 | E7: ATIBALLI+NEELMANGLA | F7: ANGUL ODISSA | G7: 54580 | H7: 54580 | J7: 45775 | K7: ALL FREIGHT CLEAR NO DUES | L7: DONE
A8: 7 | B8: 45782 | C8: JH01KD-0526 | D8: Customer 01 | E8: KRISHNAGIRI | F8: DHULAGARH | G8: 50490 | H8: 50490 | J8: 45792 | K8: ALL FREIGHT CLEAR NO DUES | L8: DONE
A9: 8 | B9: 45782 | C9: JH01KD-6142 | D9: Customer 02 | E9: ATIBALLI+NEELMANGLA | F9: BURGED ODISSA | G9: 56100 | H9: 56100 | J9: 45783 | K9: ALL FREIGHT CLEAR NO DUES | L9: DONE
A10: 9 | B10: 45784 | C10: JH01KD-2417 | D10: Customer 01 | E10: KRISHNAGIRI | F10: RANCHI | G10: 54450 | H10: 54450 | J10: 45784 | K10: ALL FREIGHT CLEAR NO DUES | L10: DONE
A11: 10 | B11: 45793 | C11: JH01KD-2417 | D11: Transporter 29 | E11: NARSAPUR | F11: TIRUPPUR | G11: 9900 | H11: 9900 | I11: - | J11: 45840 | K11: ALL FREIGHT CLEAR NO DUES | L11: DONE
A12: 11 | B12: 45796 | C12: JH01KD-6142 | D12: Customer 02 | E12: ATIBALLI+JIGNI | F12: SAMBALPUR ODISSA | G12: 56100 | H12: 56100 | J12: 45798 | K12: ALL FREIGHT CLEAR NO DUES | L12: DONE
A13: 12 | B13: 45813 | C13: JH01KD-0526 | D13: Transporter 33 | E13: NARSAPUR | F13: TIRCHY | G13: 14520 | H13: 14520 | J13: 45819 | K13: ALL FREIGHT CLEAR NO DUES | L13: DONE
A14: 13 | B14: 45814 | C14: JH01KD-6142 | D14: Customer 02 | E14: JIGNI+NEELMANGLA | F14: DHULAGARH | G14: 54780 | H14: 54780 | J14: 45814 | K14: ALL FREIGHT CLEAR NO DUES | L14: DONE
A15: 14 | B15: 45817 | C15: JH01KD-6142 | D15: Customer 05 | E15: HOWRAH | F15: RANCHI | G15: 16500 | H15: 16500 | J15: 45819 | K15: ALL FREIGHT CLEAR NO DUES | L15: DONE
A16: 15 | B16: 45836 | C16: JH01KD-0526 | D16: Transporter 33 | E16: NARSAPUR | F16: DURGAPUR | G16: 56100 | H16: 56100 | I16: - | J16: 45884 | K16: ALL FREIGHT CLEAR NO DUES | L16: DONE
A17: 16 | B17: 45841 | C17: JH01KM-8803 | D17: Customer 02 | E17: K.R.PURAM BANGLORE | F17: BRAHMAPUR,ODISSA | G17: 49500 | H17: 49500 | J17: 45843 | K17: ALL FREIGHT CLEAR NO DUES | L17: DONE
A18: 17 | B18: 45844 | C18: JH01KM-8803 | D18: Customer 06 | E18: BRAHMAPUR | F18: KEONJHAR | G18: 6600 | H18: 6600 | I18: - | J18: 45844 | K18: ALL FREIGHT CLEAR NO DUES | L18: DONE
A19: 17 | B19: 45841 | C19: JH01KD-3958 | D19: Customer 02 | E19: JIGNI,BNG | F19: PATNA | G19: 58080 | H19: 58080 | J19: 45843 | K19: ALL FREIGHT CLEAR NO DUES | L19: DONE
A20: 18 | B20: 45843 | C20: JH01KD-6142 | D20: Customer 01 | E20: KRISHNAGIRI | F20: RANCHI | G20: 52470 | H20: 52470 | J20: 45846 | K20: ALL FREIGHT CLEAR NO DUES | L20: DONE
A21: 19 | B21: 45851 | C21: JH01KD-2417 | D21: Customer 07 | E21: NEELMANGLA | F21: RANCHI | G21: 59400 | H21: 59400 | I21: - | J21: 45930 | K21: ALL FREIGHT CLEAR NO DUES | L21: DONE
A22: 20 | B22: 45860 | C22: JH01KD-2417 | D22: Customer 01 | E22: KRISHNAGIRI | F22: DHULAGARH | G22: 48840 | H22: 48840 | I22: - | J22: 45863 | K22: ALL FREIGHT CLEAR NO DUES | L22: DONE
A23: 21 | B23: 45876 | C23: JH01KD-6142 | D23: Customer 01 | E23: KRISHNAGIRI | F23: RANCHI | G23: 49500 | H23: 49500 | I23: - | J23: - | K23: ALL FREIGHT CLEAR NO DUES | L23: DONE
A24: 22 | B24: 45883 | C24: JH01KM-8803 | D24: Customer 02 | E24: JIGNI | F24: PATNA | G24: 52800 | H24: 52800 | I24: - | J24: 45885 | K24: ALL FREIGHT CLEAR NO DUES | L24: DONE
A25: 23 | B25: 45886 | C25: JH01KD-3958 | D25: Customer 02 | E25: JIGNI | F25: PATNA | G25: 52800 | H25: 52800 | I25: - | J25: 45890 | K25: ALL FREIGHT CLEAR NO DUES | L25: DONE
A26: 24 | B26: 45887 | C26: JH01KD-6142 | D26: Customer 02 | E26: JIGNI | F26: PATNA | G26: 52800 | H26: 5280 | I26: - | J26: 45890 | K26: ALL FREIGHT CLEAR NO DUES | L26: DONE
A27: 25 | B27: 45891 | C27: JH01KD-0526 | D27: Customer 02 | E27: DODABALLAPUR | F27: KOLKATA | G27: 48180 | H27: 48180 | I27: - | J27: - | K27: ALL FREIGHT CLEAR NO DUES | L27: DONE
A28: 26 | B28: 45892 | C28: JH01KD2417 | D28: Customer 01 | E28: KRISHNAGIRI | F28: RANCHI | G28: 49170 | H28: 49170 | I28: - | J28: - | K28: ALL FREIGHT CLEAR NO DUES | L28: DONE
A29: 57 | B29: 45894 | C29: BR24XY-8129 | D29: Customer 01 | E29: CHENNAI | F29: KOLKATA | G29: 46860 | H29: 46860 | I29: - | J29: 26-08-205 | K29: ALL FREIGHT CLEAR NO DUES | L29: DONE
A30: 58 | B30: 45904 | C30: JH01KD-3958 | D30: Customer 02 | E30: JIGNI | F30: PATNA | G30: 54120 | H30: 54120 | I30: - | J30: 46000 | K30: ALL FREIGHT CLEAR NO DUES | L30: DONE
A31: 59 | B31: 45910 | C31: JH01KD-0526 | D31: Customer 02 | E31: JIGNI | F31: PATNA | G31: 54120 | H31: 54120 | I31: - | J31: - | K31: ALL FREIGHT CLEAR NO DUES | L31: DONE
A32: 60 | B32: 45915 | C32: JH01KD-6142 | D32: Customer 01 | E32: NEELMANGLA | F32: KOLKATA | G32: 47520 | H32: 47520 | I32: - | J32: - | K32: ALL FREIGHT CLEAR NO DUES | L32: DONE
A33: 61 | B33: 45917 | C33: JH01KD-3958 | D33: Customer 02 | E33: JIGNI | F33: PATNA | G33: 54120 | H33: 54120 | I33: - | J33: - | K33: ALL FREIGHT CLEAR NO DUES | L33: DONE
A34: 62 | B34: 45920 | C34: BR24XY-8129 | D34: Customer 01 | E34: KRISHNAGIRI | F34: DHULAGARH | G34: 48510 | H34: 48510 | I34: - | J34: - | K34: ALL FREIGHT CLEAR NO DUES | L34: DONE
A35: 63 | B35: 45926 | C35: BR24XY-8129 | D35: BN | E35: KOLKATA | F35: RANCHI | G35: 16500 | H35: 16500 | I35: - | J35: 45940 | K35: ALL FREIGHT CLEAR NO DUES | L35: DONE
A36: 64 | B36: 45954 | C36: JH01KD-6142 | D36: Customer 02 | E36: JIGNI | F36: BALASORE | G36: 50160 | H36: 50160 | I36: - | J36: - | K36: ALL FREIGHT CLEAR NO DUES | L36: DONE
A37: 65 | B37: 45958 | C37: JH01KD-0526 | D37: Customer 02 | E37: JIGNI | F37: BALASORE | G37: 47520 | H37: 47520 | I37: - | J37: - | K37: ALL FREIGHT CLEAR NO DUES | L37: DONE
A38: 66 | B38: 45965 | C38: JH01KD-2417 | D38: Customer 01 | E38: KRISHNAGIRI | F38: RANCHI | G38: 50160 | H38: 50160 | I38: - | J38: 45967 | K38: ALL FREIGHT CLEAR NO DUES | L38: DONE
A39: 67 | B39: 45965 | C39: JH01KD-6142 | D39: Customer 01 | E39: KRISHNAGIRI | F39: DHULAGARH | G39: 48840 | H39: 48840 | I39: - | J39: 45979 | K39: ALL FREIGHT CLEAR NO DUES | L39: DONE
A40: 68 | B40: 45968 | C40: JH01KD-0526 | D40: Customer 02 | E40: HOSUR | F40: KOLKATA | G40: 49500 | H40: 49500 | I40: - | J40: - | K40: ALL FREIGHT CLEAR NO DUES | L40: DONE
...

Sheet MARKET LOAD CLEAN
A1: MARKET LOAD REGISTER — BN LOGISTICS (own trucks sold outside Auburn)
A2: LOADS | B2: =SUMPRODUCT(--(MARKET[LOAD DATE]<>"")) -> 171 | D2: REVENUE | E2: =SUM(MARKET[RATE (₹)]) -> 6780690 | G2: AVG LOAD VALUE | H2: =IFERROR(AVERAGE(MARKET[RATE (₹)]),"") -> 39653.158 | J2: Blue = you type it
A3: PERIOD | B3: =TEXT(MIN(MARKET[LOAD DATE]),"mmm yyyy")&" to "&TEXT(MAX(MARKET[LOAD DATE]),"mmm yyyy") -> Apr 2025 to Sep 2026 | D3: RECEIVED | E3: =SUM(MARKET[ADVANCE RECEIVED (₹)]) -> 6558710 | G3: AVG DAYS TO RECEIVE | H3: =IFERROR(AVERAGE(MARKET[DAYS TO RECEIVE]),"") -> 7.0625 | J3: Black = calculated, do not type
A4: CUSTOMERS | B4: =SUMPRODUCT((MARKET[CUSTOMER NAME]<>"")/COUNTIF(MARKET[CUSTOMER NAME],MARKET[CUSTOMER NAME]&"")) -> 24 | D4: BALANCE DUE | E4: =SUM(MARKET[BALANCE DUE (₹)]) -> 192280 | G4: POD NOT DONE | H4: =COUNTIF(MARKET[LOAD DATE],">0")-COUNTIF(MARKET[POD STATUS],"DONE") -> 27 | J4: BALANCE DUE = RATE − ADVANCE RECEIVED
A6: S.NO. | B6: LOAD DATE | C6: MONTH | D6: LORRY NO. | E6: CUSTOMER NAME | F6: LOAD FROM | G6: DELIVERY POINT | H6: RATE (₹) | I6: ADVANCE RECEIVED (₹) | J6: BALANCE DUE (₹) | K6: ADVANCE RECEIVED DATE | L6: DAYS TO RECEIVE | M6: POD STATUS | N6: POD REF | O6: REMARKS | P6: POD AS LOGGED
A7: =IF($B7="","",ROW()-6) -> 1 | B7: 45756 | C7: =IF($B7="","",EOMONTH($B7,-1)+1) -> 45748 | D7: JH01KD-6142 | E7: Customer 01 | F7: KRISHNAGIRI | G7: RANCHI | H7: 54450 | I7: 54450 | J7: =IF(OR($H7="",$I7=""),"",$H7-$I7) -> 0 | K7: 45761 | L7: =IF(OR($B7="",$K7=""),"",$K7-$B7) -> 5 | M7: DONE | O7: ALL FREIGHT CLEAR NO DUES | P7: DONE
A8: =IF($B8="","",ROW()-6) -> 2 | B8: 45765 | C8: =IF($B8="","",EOMONTH($B8,-1)+1) -> 45748 | D8: JH01KD-0526 | E8: Customer 02 | F8: HOSKOTE | G8: KOLKATA | H8: 49500 | I8: 49500 | J8: =IF(OR($H8="",$I8=""),"",$H8-$I8) -> 0 | K8: 45768 | L8: =IF(OR($B8="",$K8=""),"",$K8-$B8) -> 3 | M8: DONE | O8: ALL FREIGHT CLEAR NO DUES | P8: DONE
A9: =IF($B9="","",ROW()-6) -> 3 | B9: 45768 | C9: =IF($B9="","",EOMONTH($B9,-1)+1) -> 45748 | D9: JH01KD-2417 | E9: Customer 02 | F9: MALUR | G9: BIHAR SHARIF | H9: 57420 | I9: 57420 | J9: =IF(OR($H9="",$I9=""),"",$H9-$I9) -> 0 | K9: 45772 | L9: =IF(OR($B9="",$K9=""),"",$K9-$B9) -> 4 | M9: DONE | O9: ALL FREIGHT CLEAR NO DUES | P9: DONE
A10: =IF($B10="","",ROW()-6) -> 4 | B10: 45772 | C10: =IF($B10="","",EOMONTH($B10,-1)+1) -> 45748 | D10: JH01KD-6142 | E10: Customer 01 | F10: KRISHNAGIRI | G10: DHULAGARH | H10: 49500 | I10: 49500 | J10: =IF(OR($H10="",$I10=""),"",$H10-$I10) -> 0 | K10: 45776 | L10: =IF(OR($B10="",$K10=""),"",$K10-$B10) -> 4 | M10: DONE | O10: ALL FREIGHT CLEAR NO DUES | P10: DONE
A11: =IF($B11="","",ROW()-6) -> 5 | B11: 45772 | C11: =IF($B11="","",EOMONTH($B11,-1)+1) -> 45748 | D11: JH01KD-0526 | E11: Customer 01 | F11: HOSKOTE | G11: DHULAGARH | H11: 49830 | I11: 49830 | J11: =IF(OR($H11="",$I11=""),"",$H11-$I11) -> 0 | K11: 45778 | L11: =IF(OR($B11="",$K11=""),"",$K11-$B11) -> 6 | M11: DONE | O11: ALL FREIGHT CLEAR NO DUES | P11: DONE
A12: =IF($B12="","",ROW()-6) -> 6 | B12: 45773 | C12: =IF($B12="","",EOMONTH($B12,-1)+1) -> 45748 | D12: JH01KM-8803 | E12: Customer 02 | F12: ATIBALLI+NEELMANGLA | G12: ANGUL ODISSA | H12: 54580 | I12: 54580 | J12: =IF(OR($H12="",$I12=""),"",$H12-$I12) -> 0 | K12: 45775 | L12: =IF(OR($B12="",$K12=""),"",$K12-$B12) -> 2 | M12: DONE | O12: ALL FREIGHT CLEAR NO DUES | P12: DONE
A13: =IF($B13="","",ROW()-6) -> 7 | B13: 45782 | C13: =IF($B13="","",EOMONTH($B13,-1)+1) -> 45778 | D13: JH01KD-0526 | E13: Customer 01 | F13: KRISHNAGIRI | G13: DHULAGARH | H13: 50490 | I13: 50490 | J13: =IF(OR($H13="",$I13=""),"",$H13-$I13) -> 0 | K13: 45792 | L13: =IF(OR($B13="",$K13=""),"",$K13-$B13) -> 10 | M13: DONE | O13: ALL FREIGHT CLEAR NO DUES | P13: DONE
A14: =IF($B14="","",ROW()-6) -> 8 | B14: 45782 | C14: =IF($B14="","",EOMONTH($B14,-1)+1) -> 45778 | D14: JH01KD-6142 | E14: Customer 02 | F14: ATIBALLI+NEELMANGLA | G14: BURGED ODISSA | H14: 56100 | I14: 56100 | J14: =IF(OR($H14="",$I14=""),"",$H14-$I14) -> 0 | K14: 45783 | L14: =IF(OR($B14="",$K14=""),"",$K14-$B14) -> 1 | M14: DONE | O14: ALL FREIGHT CLEAR NO DUES | P14: DONE
A15: =IF($B15="","",ROW()-6) -> 9 | B15: 45784 | C15: =IF($B15="","",EOMONTH($B15,-1)+1) -> 45778 | D15: JH01KD-2417 | E15: Customer 01 | F15: KRISHNAGIRI | G15: RANCHI | H15: 54450 | I15: 54450 | J15: =IF(OR($H15="",$I15=""),"",$H15-$I15) -> 0 | K15: 45784 | L15: =IF(OR($B15="",$K15=""),"",$K15-$B15) -> 0 | M15: DONE | O15: ALL FREIGHT CLEAR NO DUES | P15: DONE
A16: =IF($B16="","",ROW()-6) -> 10 | B16: 45793 | C16: =IF($B16="","",EOMONTH($B16,-1)+1) -> 45778 | D16: JH01KD-2417 | E16: Transporter 29 | F16: NARSAPUR | G16: TIRUPPUR | H16: 9900 | I16: 9900 | J16: =IF(OR($H16="",$I16=""),"",$H16-$I16) -> 0 | K16: 45840 | L16: =IF(OR($B16="",$K16=""),"",$K16-$B16) -> 47 | M16: DONE | O16: ALL FREIGHT CLEAR NO DUES | P16: DONE
A17: =IF($B17="","",ROW()-6) -> 11 | B17: 45796 | C17: =IF($B17="","",EOMONTH($B17,-1)+1) -> 45778 | D17: JH01KD-6142 | E17: Customer 02 | F17: ATIBALLI+JIGNI | G17: SAMBALPUR ODISSA | H17: 56100 | I17: 56100 | J17: =IF(OR($H17="",$I17=""),"",$H17-$I17) -> 0 | K17: 45798 | L17: =IF(OR($B17="",$K17=""),"",$K17-$B17) -> 2 | M17: DONE | O17: ALL FREIGHT CLEAR NO DUES | P17: DONE
